Traceback (most recent call last):
  File "/opt/hostedtoolcache/Python/3.9.18/x64/lib/python3.9/site-packages/jupyter_cache/executors/utils.py", line 58, in single_nb_execution
    executenb(
  File "/opt/hostedtoolcache/Python/3.9.18/x64/lib/python3.9/site-packages/nbclient/client.py", line 1305, in execute
    return NotebookClient(nb=nb, resources=resources, km=km, **kwargs).execute()
  File "/opt/hostedtoolcache/Python/3.9.18/x64/lib/python3.9/site-packages/jupyter_core/utils/__init__.py", line 165, in wrapped
    return loop.run_until_complete(inner)
  File "/opt/hostedtoolcache/Python/3.9.18/x64/lib/python3.9/asyncio/base_events.py", line 647, in run_until_complete
    return future.result()
  File "/opt/hostedtoolcache/Python/3.9.18/x64/lib/python3.9/site-packages/nbclient/client.py", line 705, in async_execute
    await self.async_execute_cell(
  File "/opt/hostedtoolcache/Python/3.9.18/x64/lib/python3.9/site-packages/nbclient/client.py", line 1058, in async_execute_cell
    await self._check_raise_for_error(cell, cell_index, exec_reply)
  File "/opt/hostedtoolcache/Python/3.9.18/x64/lib/python3.9/site-packages/nbclient/client.py", line 914, in _check_raise_for_error
    raise CellExecutionError.from_cell_and_msg(cell, exec_reply_content)
nbclient.exceptions.CellExecutionError: An error occurred while executing the following cell:
------------------
# import libraries
from transformers import (
    AutoTokenizer, 
    AutoModelForCausalLM
)
import torch
from datasets import (
    load_dataset,
    Dataset
)
from trl import AutoModelForCausalLMWithValueHead, PPOConfig, PPOTrainer
import evaluate
------------------

----- stderr -----
/opt/hostedtoolcache/Python/3.9.18/x64/lib/python3.9/site-packages/tqdm/auto.py:21: TqdmWarning: IProgress not found. Please update jupyter and ipywidgets. See https://ipywidgets.readthedocs.io/en/stable/user_install.html
  from .autonotebook import tqdm as notebook_tqdm
------------------

[0;31m---------------------------------------------------------------------------[0m
[0;31mModuleNotFoundError[0m                       Traceback (most recent call last)
Cell [0;32mIn[2], line 11[0m
[1;32m      6[0m [38;5;28;01mimport[39;00m [38;5;21;01mtorch[39;00m
[1;32m      7[0m [38;5;28;01mfrom[39;00m [38;5;21;01mdatasets[39;00m [38;5;28;01mimport[39;00m (
[1;32m      8[0m     load_dataset,
[1;32m      9[0m     Dataset
[1;32m     10[0m )
[0;32m---> 11[0m [38;5;28;01mfrom[39;00m [38;5;21;01mtrl[39;00m [38;5;28;01mimport[39;00m AutoModelForCausalLMWithValueHead, PPOConfig, PPOTrainer
[1;32m     12[0m [38;5;28;01mimport[39;00m [38;5;21;01mevaluate[39;00m

[0;31mModuleNotFoundError[0m: No module named 'trl'

